# 学习日记 20年03月09日

#### generator 复习

之前学习的时候，遗漏了一些重要的点吧，所以复盘一下。
> 我们都知道 gen() 返回的是一个遍历器对象，假设它叫iterator
> 这个对象常用的有next方法。其实另外两个也蛮重要的就是throw(), return()
> 其实这三者都是使该函数返回执行状态，不同的地方就是方法的语义上。
```
function* gen() {
  yield 'x';
  yield 'y';
  return 'z'
}
const iterator = gen()

// 例如next()
iterator.next() // 执行到遇到的第一个yield语句 并返回 { done: false, value: 'x'}

// 例如throw()
iterator.throw(arg) // 执行到遇到的第一个yield语句 并把yield 变成 throw arg语句

// 例如return()
iterator.return(arg) // 执行到遇到的第一个yield语句 并把yield 变成 return arg语句

```

也正因这些方法，迭代器对象具有这些性质
* 能够控制函数的执行与返回
* 函数体内外的数据交换
* 错误处理机制

#### async函数

这里扩展下，async函数是generator函数的语法糖。
假如说一个promise状态变成reject我们应该怎么处理？

```
async function request () {
  await promiseInstance
}
```

我们可以先记结论，等promise状态变为reject后，继续执行函数，但此时 await变成了 throw 

```
reject('error')
//回到request函数中
throw 'error'
```

因为此时，没有try-catch捕获throw问题的话，会导致下面的原因
1. 导致函数无法执行下去
2. async函数返回的promise状态 永远都是 pending

所以 如果是使用了await promise语法 尽可能的使用try catch